Workbook

Sheet Objectives
B2: Objectives
B4: Objective: | D4: Objective 1
B6: Activity | D6: Rationale | E6: Owned By | F6: Benchmark | G6: Success Outcome | I6: Target Completion Date
B7: Activity 1 | D7: How will this activity help us meet the objective? | E7: Who is responsible? | F7: Current situation | G7: What would success look like? | I7: 44561
B8: Activity 1 | D8: How will this activity help us meet the objective? | E8: Who is responsible? | F8: Current situation | G8: What would success look like? | I8: 44561
B9: Activity 1 | D9: How will this activity help us meet the objective? | E9: Who is responsible? | F9: Current situation | G9: What would success look like? | I9: 44561
B10: Activity 1 | D10: How will this activity help us meet the objective? | E10: Who is responsible? | F10: Current situation | G10: What would success look like? | I10: 44561
B11: Activity 1 | D11: How will this activity help us meet the objective? | E11: Who is responsible? | F11: Current situation | G11: What would success look like? | I11: 44561
B12: Activity 1 | D12: How will this activity help us meet the objective? | E12: Who is responsible? | F12: Current situation | G12: What would success look like? | I12: 44561
B14: Objective: | D14: Objective 2
B16: Activity | D16: Rationale | E16: Owned By | F16: Benchmark | G16: Success Outcome | I16: Target Completion Date
B17: Activity 1 | D17: How will this activity help us meet the objective? | E17: Who is responsible? | F17: Current situation | G17: What would success look like? | I17: 44561
B18: Activity 1 | D18: How will this activity help us meet the objective? | E18: Who is responsible? | F18: Current situation | G18: What would success look like? | I18: 44561
B19: Activity 1 | D19: How will this activity help us meet the objective? | E19: Who is responsible? | F19: Current situation | G19: What would success look like? | I19: 44561
B20: Activity 1 | D20: How will this activity help us meet the objective? | E20: Who is responsible? | F20: Current situation | G20: What would success look like? | I20: 44561
B21: Activity 1 | D21: How will this activity help us meet the objective? | E21: Who is responsible? | F21: Current situation | G21: What would success look like? | I21: 44561
B22: Activity 1 | D22: How will this activity help us meet the objective? | E22: Who is responsible? | F22: Current situation | G22: What would success look like? | I22: 44561
B24: Objective: | D24: Objective 3
B26: Activity | D26: Rationale | E26: Owned By | F26: Benchmark | G26: Success Outcome | I26: Target Completion Date
B27: Activity 1 | D27: How will this activity help us meet the objective? | E27: Who is responsible? | F27: Current situation | G27: What would success look like? | I27: 44561
B28: Activity 1 | D28: How will this activity help us meet the objective? | E28: Who is responsible? | F28: Current situation | G28: What would success look like? | I28: 44561
B29: Activity 1 | D29: How will this activity help us meet the objective? | E29: Who is responsible? | F29: Current situation | G29: What would success look like? | I29: 44561
B30: Activity 1 | D30: How will this activity help us meet the objective? | E30: Who is responsible? | F30: Current situation | G30: What would success look like? | I30: 44561
B31: Activity 1 | D31: How will this activity help us meet the objective? | E31: Who is responsible? | F31: Current situation | G31: What would success look like? | I31: 44561
B32: Activity 1 | D32: How will this activity help us meet the objective? | E32: Who is responsible? | F32: Current situation | G32: What would success look like? | I32: 44561

Sheet Skill Gaps
B2: Skill Gaps
B4: Department: | C4: Department 1
B6: Skill | C6: Rationale | D6: How we can improve
B7: Skill gap | C7: Why is this skill important? | D7: e.g. through hiring, training, contracting out, or redeploying existing resources.
B8: Skill gap | C8: Why is this skill important? | D8: e.g. through hiring, training, contracting out, or redeploying existing resources.
B9: Skill gap | C9: Why is this skill important? | D9: e.g. through hiring, training, contracting out, or redeploying existing resources.
B11: Department: | C11: Department 2
B13: Skill | C13: Rationale | D13: How we can improve
B14: Skill gap | C14: Why is this skill important? | D14: e.g. through hiring, training, contracting out, or redeploying existing resources.
B15: Skill gap | C15: Why is this skill important? | D15: e.g. through hiring, training, contracting out, or redeploying existing resources.
B16: Skill gap | C16: Why is this skill important? | D16: e.g. through hiring, training, contracting out, or redeploying existing resources.
B18: Department: | C18: Department 3
B20: Skill | C20: Rationale | D20: How we can improve
B21: Skill gap | C21: Why is this skill important? | D21: e.g. through hiring, training, contracting out, or redeploying existing resources.
B22: Skill gap | C22: Why is this skill important? | D22: e.g. through hiring, training, contracting out, or redeploying existing resources.
B23: Skill gap | C23: Why is this skill important? | D23: e.g. through hiring, training, contracting out, or redeploying existing resources.

Sheet Headcount Planning
B2: Headcount Planning
B3: Updates to this tab will be reflected in sourcing plan and budget
E5: Current | F5: Month 1 | G5: Month 2 | H5: Month 3 | I5: Month 4 | J5: Month 5 | K5: Month 6 | L5: Month 7 | M5: Month 8 | N5: Month 9 | O5: Month 10 | P5: Month 11 | Q5: Month 12 | R5: Change
B6: Department 1
C7: Role 1
D8: Target Headcount | E8: 1 | F8: 1 | G8: 1 | H8: 1 | I8: 1 | J8: 2 | K8: 2 | L8: 3 | M8: 3 | N8: 3 | O8: 3 | P8: 3 | Q8: 3 | R8: =Q8-E8 -> 2
D9: Forecast Turnover / Attrition
D10: New Starters Required | F10: =F8-(E8-F9) -> 0 | G10: =G8-(F8-G9) -> 0 | H10: =H8-(G8-H9) -> 0 | I10: =I8-(H8-I9) -> 0 | J10: =J8-(I8-J9) -> 1 | K10: =K8-(J8-K9) -> 0 | L10: =L8-(K8-L9) -> 1 | M10: =M8-(L8-M9) -> 0 | ... Q10: =Q8-(P8-Q9) -> 0
C11: Role 2
D12: Target Headcount | E12: 4 | F12: 4 | G12: 4 | H12: 4 | I12: 4 | J12: 4 | K12: 4 | L12: 4 | M12: 4 | N12: 4 | O12: 4 | P12: 4 | Q12: 4 | R12: =Q12-E12 -> 0
D13: Forecast Turnover / Attrition | M13: 1
D14: New Starters Required | F14: =F12-(E12-F13) -> 0 | G14: =G12-(F12-G13) -> 0 | H14: =H12-(G12-H13) -> 0 | I14: =I12-(H12-I13) -> 0 | J14: =J12-(I12-J13) -> 0 | K14: =K12-(J12-K13) -> 0 | L14: =L12-(K12-L13) -> 0 | M14: =M12-(L12-M13) -> 1 | ... Q14: =Q12-(P12-Q13) -> 0
C15: Role 3
D16: Target Headcount | E16: 3 | F16: 4 | G16: 5 | H16: 6 | I16: 6 | J16: 6 | K16: 6 | L16: 6 | M16: 6 | N16: 6 | O16: 6 | P16: 6 | Q16: 6 | R16: =Q16-E16 -> 3
D17: Forecast Turnover / Attrition | K17: 1
D18: New Starters Required | F18: =F16-(E16-F17) -> 1 | G18: =G16-(F16-G17) -> 1 | H18: =H16-(G16-H17) -> 1 | I18: =I16-(H16-I17) -> 0 | J18: =J16-(I16-J17) -> 0 | K18: =K16-(J16-K17) -> 1 | L18: =L16-(K16-L17) -> 0 | M18: =M16-(L16-M17) -> 0 | ... Q18: =Q16-(P16-Q17) -> 0
B20: Total Headcount | E20: =E8+E12+E16 -> 8 | F20: =F8+F12+F16 -> 9 | G20: =G8+G12+G16 -> 10 | H20: =H8+H12+H16 -> 11 | I20: =I8+I12+I16 -> 11 | J20: =J8+J12+J16 -> 12 | K20: =K8+K12+K16 -> 12 | L20: =L8+L12+L16 -> 13 | ... Q20: =Q8+Q12+Q16 -> 13
B21: Change in Headcount | F21: =F20-E20 -> 1 | G21: =G20-F20 -> 1 | H21: =H20-G20 -> 1 | I21: =I20-H20 -> 0 | J21: =J20-I20 -> 1 | K21: =K20-J20 -> 0 | L21: =L20-K20 -> 1 | M21: =M20-L20 -> 0 | ... Q21: =Q20-P20 -> 0
B22: Total Hires | F22: =F10+F14+F18 -> 1 | G22: =G10+G14+G18 -> 1 | H22: =H10+H14+H18 -> 1 | I22: =I10+I14+I18 -> 0 | J22: =J10+J14+J18 -> 1 | K22: =K10+K14+K18 -> 1 | L22: =L10+L14+L18 -> 1 | M22: =M10+M14+M18 -> 1 | ... Q22: =Q10+Q14+Q18 -> 0
B24: Department 2
C25: Role 1
D26: Target Headcount | E26: 8 | F26: 8 | G26: 8 | H26: 8 | I26: 8 | J26: 8 | K26: 8 | L26: 8 | M26: 8 | N26: 8 | O26: 8 | P26: 8 | Q26: 8 | R26: =Q26-E26 -> 0
D27: Forecast Turnover / Attrition
D28: New Starters Required | F28: =F26-(E26-F27) -> 0 | G28: =G26-(F26-G27) -> 0 | H28: =H26-(G26-H27) -> 0 | I28: =I26-(H26-I27) -> 0 | J28: =J26-(I26-J27) -> 0 | K28: =K26-(J26-K27) -> 0 | L28: =L26-(K26-L27) -> 0 | M28: =M26-(L26-M27) -> 0 | ... Q28: =Q26-(P26-Q27) -> 0
C29: Role 2
D30: Target Headcount | E30: 7 | F30: 8 | G30: 9 | H30: 10 | I30: 11 | J30: 12 | K30: 13 | L30: 15 | M30: 17 | N30: 17 | O30: 17 | P30: 17 | Q30: 17 | R30: =Q30-E30 -> 10
D31: Forecast Turnover / Attrition | G31: 1
D32: New Starters Required | F32: =F30-(E30-F31) -> 1 | G32: =G30-(F30-G31) -> 2 | H32: =H30-(G30-H31) -> 1 | I32: =I30-(H30-I31) -> 1 | J32: =J30-(I30-J31) -> 1 | K32: =K30-(J30-K31) -> 1 | L32: =L30-(K30-L31) -> 2 | M32: =M30-(L30-M31) -> 2 | ... Q32: =Q30-(P30-Q31) -> 0
C33: Role 3
D34: Target Headcount | E34: 18 | F34: 18 | G34: 18 | H34: 19 | I34: 19 | J34: 19 | K34: 20 | L34: 20 | M34: 20 | N34: 21 | O34: 21 | P34: 21 | Q34: 22 | R34: =Q34-E34 -> 4
D35: Forecast Turnover / Attrition | I35: 1 | M35: 1
D36: New Starters Required | F36: =F34-(E34-F35) -> 0 | G36: =G34-(F34-G35) -> 0 | H36: =H34-(G34-H35) -> 1 | I36: =I34-(H34-I35) -> 1 | J36: =J34-(I34-J35) -> 0 | K36: =K34-(J34-K35) -> 1 | L36: =L34-(K34-L35) -> 0 | M36: =M34-(L34-M35) -> 1 | ... Q36: =Q34-(P34-Q35) -> 1
B38: Total Headcount | E38: =E26+E30+E34 -> 33 | F38: =F26+F30+F34 -> 34 | G38: =G26+G30+G34 -> 35 | H38: =H26+H30+H34 -> 37 | I38: =I26+I30+I34 -> 38 | J38: =J26+J30+J34 -> 39 | K38: =K26+K30+K34 -> 41 | L38: =L26+L30+L34 -> 43 | ... Q38: =Q26+Q30+Q34 -> 47
B39: Change in Headcount | F39: =F38-E38 -> 1 | G39: =G38-F38 -> 1 | H39: =H38-G38 -> 2 | I39: =I38-H38 -> 1 | J39: =J38-I38 -> 1 | K39: =K38-J38 -> 2 | L39: =L38-K38 -> 2 | M39: =M38-L38 -> 2 | ... Q39: =Q38-P38 -> 1
B40: Total Hires | F40: =F28+F32+F36 -> 1 | G40: =G28+G32+G36 -> 2 | H40: =H28+H32+H36 -> 2 | I40: =I28+I32+I36 -> 2 | J40: =J28+J32+J36 -> 1 | K40: =K28+K32+K36 -> 2 | L40: =L28+L32+L36 -> 2 | M40: =M28+M32+M36 -> 3 | ... Q40: =Q28+Q32+Q36 -> 1
B42: Department 3
C43: Role 1
D44: Target Headcount | E44: 1 | F44: 1 | G44: 1 | H44: 1 | I44: 1 | J44: 2 | K44: 2 | L44: 2 | M44: 2 | N44: 2 | O44: 2 | P44: 2 | Q44: 2 | R44: =Q44-E44 -> 1
D45: Forecast Turnover / Attrition
D46: New Starters Required | F46: =F44-(E44-F45) -> 0 | G46: =G44-(F44-G45) -> 0 | H46: =H44-(G44-H45) -> 0 | I46: =I44-(H44-I45) -> 0 | J46: =J44-(I44-J45) -> 1 | K46: =K44-(J44-K45) -> 0 | L46: =L44-(K44-L45) -> 0 | M46: =M44-(L44-M45) -> 0 | ... Q46: =Q44-(P44-Q45) -> 0
...

Sheet Sourcing Plan
B2: Sourcing Plan
B3: Updates to this tab will be reflected in the budget
G5: Hired Via External Recruiter | K5: Direct Hires | O5: Employee Referrals
D6: Hires Required | E6: Hires in Sourcing Plan | F6: Avg Salary | G6: Hires Via Recruiters | H6: Recruter Fee (% of Salary) | I6: Recruiter Fee Per Hire | J6: Total Recruiter Fees | K6: Direct Hires | L6: Advertising Cost (% of Salary) | M6: Advertising Cost / Hire | N6: Total Recruitment Marketing | O6: # from Employee Referals | P6: Cost of Incentive Per Hire | Q6: Total Employee Referrals | R6: Total Sourcing Cost
B7: Department 1
C8: Role 1 | D8: =SUM('Headcount Planning'!F10:Q10) -> 2 | E8: =G8+K8+O8 -> 2 | F8: 100000 | G8: 1 | H8: 0.25 | I8: =H8*F8 -> 25000 | J8: =I8*G8 -> 25000 | K8: 0 | L8: 0.04 | M8: =L8*F8 -> 4000 | N8: =M8*K8 -> 0 | O8: 1 | P8: 2000 | Q8: =P8*O8 -> 2000 | R8: =Q8+N8+J8 -> 27000
C9: Role 2 | D9: =SUM('Headcount Planning'!F14:Q14) -> 1 | E9: =G9+K9+O9 -> 1 | F9: 80000 | G9: 0 | H9: 0.25 | I9: =H9*F9 -> 20000 | J9: =I9*G9 -> 0 | K9: =D9-G9 -> 1 | L9: 0.03 | M9: =L9*F9 -> 2400 | N9: =M9*K9 -> 2400 | O9: 0 | P9: 2000 | Q9: =P9*O9 -> 0 | R9: =Q9+N9+J9 -> 2400
C10: Role 3 | D10: =SUM('Headcount Planning'!F18:Q18) -> 4 | E10: =G10+K10+O10 -> 4 | F10: 35000 | G10: 1 | H10: 0.25 | I10: =H10*F10 -> 8750 | J10: =I10*G10 -> 8750 | K10: 3 | L10: 0.03 | M10: =L10*F10 -> 1050 | N10: =M10*K10 -> 3150 | O10: 0 | P10: 2000 | Q10: =P10*O10 -> 0 | R10: =Q10+N10+J10 -> 11900
B11: Department 2
C12: Role 1 | D12: =SUM('Headcount Planning'!F28:Q28) -> 0 | E12: =G12+K12+O12 -> 0 | F12: 90000 | G12: 0 | H12: 0.25 | I12: =H12*F12 -> 22500 | J12: =I12*G12 -> 0 | K12: =D12-G12 -> 0 | L12: 0.03 | M12: =L12*F12 -> 2700 | N12: =M12*K12 -> 0 | O12: 0 | P12: 2000 | Q12: =P12*O12 -> 0 | R12: =Q12+N12+J12 -> 0
C13: Role 2 | D13: =SUM('Headcount Planning'!F32:Q32) -> 11 | E13: =G13+K13+O13 -> 11 | F13: 20000 | G13: 0 | H13: 0.25 | I13: =H13*F13 -> 5000 | J13: =I13*G13 -> 0 | K13: 8 | L13: 0.03 | M13: =L13*F13 -> 600 | N13: =M13*K13 -> 4800 | O13: 3 | P13: 2000 | Q13: =P13*O13 -> 6000 | R13: =Q13+N13+J13 -> 10800
C14: Role 3 | D14: =SUM('Headcount Planning'!F36:Q36) -> 6 | E14: =G14+K14+O14 -> 6 | F14: 40000 | G14: 2 | H14: 0.25 | I14: =H14*F14 -> 10000 | J14: =I14*G14 -> 20000 | K14: 4 | L14: 0.03 | M14: =L14*F14 -> 1200 | N14: =M14*K14 -> 4800 | O14: 0 | P14: 2000 | Q14: =P14*O14 -> 0 | R14: =Q14+N14+J14 -> 24800
B15: Department 3
C16: Role 1 | D16: =SUM('Headcount Planning'!F46:Q46) -> 1 | E16: =G16+K16+O16 -> 1 | F16: 70000 | G16: 0 | H16: 0.25 | I16: =H16*F16 -> 17500 | J16: =I16*G16 -> 0 | K16: =D16-G16 -> 1 | L16: 0.03 | M16: =L16*F16 -> 2100 | N16: =M16*K16 -> 2100 | O16: 0 | P16: 2000 | Q16: =P16*O16 -> 0 | R16: =Q16+N16+J16 -> 2100
C17: Role 2 | D17: =SUM('Headcount Planning'!F50:Q50) -> 0 | E17: =G17+K17+O17 -> 0 | F17: 43500 | G17: 0 | H17: 0.25 | I17: =H17*F17 -> 10875 | J17: =I17*G17 -> 0 | K17: 0 | L17: 0.03 | M17: =L17*F17 -> 1305 | N17: =M17*K17 -> 0 | O17: 0 | P17: 2000 | Q17: =P17*O17 -> 0 | R17: =Q17+N17+J17 -> 0
C18: Role 3 | D18: =SUM('Headcount Planning'!F54:Q54) -> 1 | E18: =G18+K18+O18 -> 1 | F18: 38750 | G18: 0 | H18: 0.25 | I18: =H18*F18 -> 9687.5 | J18: =I18*G18 -> 0 | K18: 1 | L18: 0.03 | M18: =L18*F18 -> 1162.5 | N18: =M18*K18 -> 1162.5 | O18: 0 | P18: 2000 | Q18: =P18*O18 -> 0 | R18: =Q18+N18+J18 -> 1162.5
B19: Total | D19: =SUM(D8:D18) -> 26 | G19: =SUM(G8:G18) -> 4 | J19: =SUM(J8:J18) -> 53750 | K19: =SUM(K8:K18) -> 18 | N19: =SUM(N8:N18) -> 18412.5 | O19: =SUM(O8:O18) -> 4 | Q19: =SUM(Q8:Q18) -> 8000 | R19: =SUM(R8:R18) -> 80162.5

Sheet Summary Bugdet
B2: Summary Budget
B4: Sourcing | G4: Sourcing Cost / Hire
C5: External Recruiters | E5: ='Sourcing Plan'!J19 -> 53750 | G5: =ROUNDUP(E5/'Sourcing Plan'!G19,0) -> 13438
C6: Recruitment Marketing | E6: ='Sourcing Plan'!N19 -> 18412.5 | G6: =ROUNDUP(E6/'Sourcing Plan'!K19,0) -> 1023
C7: Employee Referral Incentives | E7: ='Sourcing Plan'!Q19 -> 8000 | G7: =ROUNDUP(E7/'Sourcing Plan'!O19,0) -> 2000
B8: Total Sourcing | E8: =SUM(E5:E7) -> 80162.5 | G8: =E8/('Sourcing Plan'!O19+'Sourcing Plan'!K19+'Sourcing Plan'!G19) -> 3083.1731
B10: Employer Branding
C11: Careers website photography | E11: 700
C12: Employer branding advertising | E12: 1500
B13: Total Employer Branding | E13: =SUM(E11:E12) -> 2200
B15: Selection
C16: Testing | E16: 1200
C17: Background checks | E17: 500
B18: Total Employer Branding | E18: =SUM(E16:E17) -> 1700
B20: Technology
C21: Applicant Tracking System | E21: 15000
C22: Onboarding Software | E22: 7500
B23: Total Technology | E23: =SUM(E21:E22) -> 22500
B25: Team
C26: Head of Talent Acquisition | E26: 70000
B27: Total Team | E27: =E26 -> 70000
B29: Total | E29: =E27+E23+E13+E8+E18 -> 176562.5 | G29: Fully Loaded Cost / Hire: | H29: =E29/'Sourcing Plan'!G19+'Sourcing Plan'!K19+'Sourcing Plan'!O19 -> 44162.625

Sheet Vacancy-Specific Marketing Plan
B2: Vacancy-Specific Marketing Plan
B4: Department | D4: Design
B5: Vacancy | D5: Mid-Weight Designer
B6: Salary | D6: 60000
B7: Launch Date | D7: 44197
B8: Close Date | D8: 44233
B10: Number of hires required | D10: 1
B11: Applicant to hire rate | D11: 0.04
B12: Target number of applicants | D12: =ROUNDUP(D10/D11,0) -> 25
B14: Forecast number of applicants | D14: =F26+F35 -> 29
B15: Budget Required | D15: =E26 -> 599
B17: Paid Distribution Activity
B18: Strategy | D18: Rationale | E18: Budget | F18: Expected number of applicants | G18: Launch Date | H18: Responsibility
B19: Job Boards
C20: Dribbble | D20: A leading job board for designers | E20: 249 | F20: 8 | G20: 44197 | H20: JS
C21: Remoters.net | D21: A well known job board for quality remote workers | E21: 0 | F21: 8 | G21: 44197 | H21: JS
B22: Programmatic
C23: Facebook | D23: Previous success hiring designers on Facebook for less than £500 / hire | E23: 350 | F23: 11 | G23: 44197 | H23: JS
C24: Instagram | D24: This will be included in the Facebook advertising budget above
B26: Total | E26: =SUM(E20:E24) -> 599 | F26: =SUM(F20:F24) -> 27
B28: Other Activity
B29: Activity | D29: Expected number of applicants | E29: Budget | F29: Expected number of applicants | G29: Launch Date | H29: Responsibility
B30: Launch on employee referral platform | E30: 0 | F30: 2 | G30: 44197 | H30: JS
B31: Share on organic social channels | D31: Facebook, Instagram, Twitter, LinkedIn | E31: 0 | G31: 44197 | H31: TM
B32: Add to Facebook jobs page | E32: 0 | G32: 44197 | H32: TM
B33: Launch on careers website | E33: 0 | G33: 44197 | H33: JS
B35: Total | E35: =SUM(E29:E33) -> 0 | F35: =SUM(F30:F34) -> 2
